Qubicle Exchange Format
Version 0.2
www.minddesk.com
8 8 8
6
0.000000 0.000000 0.000000
0.141176 0.094118 0.549020
0.333333 0.333333 0.333333
0.368627 0.250980 0.000000
0.988235 0.737255 0.690196
1.000000 1.000000 1.000000
0 6 2 2 92
0 6 3 2 28
0 6 4 2 28
0 6 5 2 60
1 2 1 4 124
1 2 6 4 124
1 4 1 4 84
1 4 2 4 20
1 4 3 4 20
1 4 4 4 20
1 4 5 4 20
1 4 6 4 52
1 5 1 4 68
1 5 2 0 4
1 5 3 4 4
1 5 4 4 4
1 5 5 0 4
1 5 6 4 36
1 6 1 2 76
1 6 2 2 8
1 6 3 2 8
1 6 4 2 8
1 6 5 2 8
1 6 6 2 44
2 2 1 5 88
2 2 2 5 20
2 2 3 5 20
2 2 4 5 20
2 2 5 5 20
2 2 6 5 56
2 3 2 5 68
2 3 3 5 4
2 3 4 5 4
2 3 5 5 36
2 4 1 4 80
2 4 2 0 0
2 4 3 0 0
2 4 4 0 0
2 4 5 4 0
2 4 6 4 48
2 5 1 4 64
2 5 2 4 0
2 5 3 4 0
2 5 4 4 0
2 5 5 0 0
2 5 6 4 32
2 6 1 2 72
2 6 2 0 0
2 6 3 0 0
2 6 4 0 0
2 6 5 0 0
2 6 6 2 40
2 7 2 2 76
2 7 3 2 12
2 7 4 2 12
2 7 5 2 44
3 0 2 4 116
3 0 5 4 116
3 1 2 1 100
3 1 5 1 100
3 2 1 5 88
3 2 2 0 0
3 2 3 5 16
3 2 4 5 16
3 2 5 0 0
3 2 6 5 56
3 3 2 5 64
3 3 3 0 0
3 3 4 0 0
3 3 5 5 32
3 4 1 4 80
3 4 2 0 0
3 4 3 0 0
3 4 4 0 0
3 4 5 4 0
3 4 6 4 48
3 5 1 3 64
3 5 2 4 0
3 5 3 4 0
3 5 4 4 0
3 5 5 0 0
3 5 6 3 32
3 6 1 2 72
3 6 2 0 0
3 6 3 0 0
3 6 4 0 0
3 6 5 0 0
3 6 6 2 40
3 7 2 2 72
3 7 3 2 8
3 7 4 2 8
3 7 5 2 40
4 0 2 4 114
4 0 5 4 114
4 1 2 1 98
4 1 5 1 98
4 2 1 5 90
4 2 2 0 0
4 2 3 5 16
4 2 4 5 16
4 2 5 0 0
4 2 6 5 58
4 3 2 5 64
4 3 3 0 0
4 3 4 0 0
4 3 5 5 32
4 4 1 4 80
4 4 2 0 0
4 4 3 0 0
4 4 4 4 0
4 4 5 0 0
4 4 6 4 48
4 5 1 4 64
4 5 2 0 0
4 5 3 4 0
4 5 4 0 0
4 5 5 0 0
4 5 6 4 32
4 6 1 2 72
4 6 2 4 0
4 6 3 0 0
4 6 4 0 0
4 6 5 0 0
4 6 6 2 40
4 7 2 2 72
4 7 3 2 8
4 7 4 2 8
4 7 5 2 40
5 2 2 5 82
5 2 3 5 18
5 2 4 5 18
5 2 5 5 50
5 3 2 5 66
5 3 3 5 2
5 3 4 5 2
5 3 5 5 34
5 4 1 4 80
5 4 2 0 0
5 4 3 4 0
5 4 4 0 0
5 4 5 0 0
5 4 6 4 48
5 5 1 3 64
5 5 2 0 0
5 5 3 4 0
5 5 4 0 0
5 5 5 0 0
5 5 6 3 32
5 6 1 2 72
5 6 2 4 0
5 6 3 0 0
5 6 4 0 0
5 6 5 0 0
5 6 6 2 40
5 7 2 2 74
5 7 3 2 10
5 7 4 2 10
5 7 5 2 42
6 4 1 4 82
6 4 2 4 18
6 4 3 4 18
6 4 4 4 18
6 4 5 4 18
6 4 6 4 50
6 5 1 3 66
6 5 2 3 2
6 5 3 3 2
6 5 4 3 2
6 5 5 3 2
6 5 6 3 34
6 6 1 2 74
6 6 2 2 10
6 6 3 2 10
6 6 4 2 10
6 6 5 2 10
6 6 6 2 42
