Qubicle Exchange Format
Version 0.2
www.minddesk.com
16 16 16
9
0.000000 0.000000 0.000000
0.000000 0.000000 1.000000
0.000000 1.000000 0.000000
0.000000 1.000000 1.000000
0.333333 0.333333 0.333333
1.000000 0.000000 0.000000
1.000000 0.000000 1.000000
1.000000 1.000000 0.000000
1.000000 1.000000 1.000000
0 0 0 8 84
0 0 1 4 30
0 0 2 4 30
0 0 3 4 30
0 0 4 4 30
0 0 5 4 30
0 0 6 4 30
0 0 7 4 30
0 0 8 4 30
0 0 9 4 30
0 0 10 4 30
0 0 11 4 30
0 0 12 4 30
0 0 13 4 30
0 0 14 4 30
0 0 15 1 52
0 1 0 4 102
0 1 15 4 102
0 2 0 4 102
0 2 15 4 102
0 3 0 4 102
0 3 15 4 102
0 4 0 4 102
0 4 15 4 102
0 5 0 4 102
0 5 15 4 102
0 6 0 4 102
0 6 15 4 102
0 7 0 4 102
0 7 15 4 102
0 8 0 4 102
0 8 15 4 102
0 9 0 4 102
0 9 15 4 102
0 10 0 4 102
0 10 15 4 102
0 11 0 4 102
0 11 15 4 102
0 12 0 4 102
0 12 15 4 102
0 13 0 4 102
0 13 15 4 102
0 14 0 4 102
0 14 15 4 102
0 15 0 2 76
0 15 1 4 30
0 15 2 4 30
0 15 3 4 30
0 15 4 4 30
0 15 5 4 30
0 15 6 4 30
0 15 7 4 30
0 15 8 4 30
0 15 9 4 30
0 15 10 4 30
0 15 11 4 30
0 15 12 4 30
0 15 13 4 30
0 15 14 4 30
0 15 15 3 44
1 0 0 4 120
1 0 15 4 120
1 15 0 4 120
1 15 15 4 120
2 0 0 4 120
2 0 15 4 120
2 15 0 4 120
2 15 15 4 120
3 0 0 4 120
3 0 15 4 120
3 15 0 4 120
3 15 15 4 120
4 0 0 4 120
4 0 15 4 120
4 15 0 4 120
4 15 15 4 120
5 0 0 4 120
5 0 15 4 120
5 15 0 4 120
5 15 15 4 120
6 0 0 4 120
6 0 15 4 120
6 15 0 4 120
6 15 15 4 120
7 0 0 4 120
7 0 15 4 120
7 15 0 4 120
7 15 15 4 120
8 0 0 4 120
8 0 15 4 120
8 15 0 4 120
8 15 15 4 120
9 0 0 4 120
9 0 15 4 120
9 15 0 4 120
9 15 15 4 120
10 0 0 4 120
10 0 15 4 120
10 15 0 4 120
10 15 15 4 120
11 0 0 4 120
11 0 15 4 120
11 15 0 4 120
11 15 15 4 120
12 0 0 4 120
12 0 15 4 120
12 15 0 4 120
12 15 15 4 120
13 0 0 4 120
13 0 15 4 120
13 15 0 4 120
13 15 15 4 120
14 0 0 4 120
14 0 15 4 120
14 15 0 4 120
14 15 15 4 120
15 0 0 5 82
15 0 1 4 30
15 0 2 4 30
15 0 3 4 30
15 0 4 4 30
15 0 5 4 30
15 0 6 4 30
15 0 7 4 30
15 0 8 4 30
15 0 9 4 30
15 0 10 4 30
15 0 11 4 30
15 0 12 4 30
15 0 13 4 30
15 0 14 4 30
15 0 15 6 50
15 1 0 4 102
15 1 15 4 102
15 2 0 4 102
15 2 15 4 102
15 3 0 4 102
15 3 15 4 102
15 4 0 4 102
15 4 15 4 102
15 5 0 4 102
15 5 15 4 102
15 6 0 4 102
15 6 15 4 102
15 7 0 4 102
15 7 15 4 102
15 8 0 4 102
15 8 15 4 102
15 9 0 4 102
15 9 15 4 102
15 10 0 4 102
15 10 15 4 102
15 11 0 4 102
15 11 15 4 102
15 12 0 4 102
15 12 15 4 102
15 13 0 4 102
15 13 15 4 102
15 14 0 4 102
15 14 15 4 102
15 15 0 7 74
15 15 1 4 30
15 15 2 4 30
15 15 3 4 30
15 15 4 4 30
15 15 5 4 30
15 15 6 4 30
15 15 7 4 30
15 15 8 4 30
15 15 9 4 30
15 15 10 4 30
15 15 11 4 30
15 15 12 4 30
15 15 13 4 30
15 15 14 4 30
15 15 15 0 42
